2023-07-04 20:12:12,030:INFO-main  Started
2023-07-04 20:12:13,177:INFO-<string>  [COLOR_AQUAMARINE_1A]Checking for potential updates...
2023-07-04 20:12:13,276:INFO-<string>  [COLOR_AQUAMARINE_1A]No updates found.
2023-07-04 20:12:18,031:INFO-<string>  [COLOR_GREEN]Successfully started the web interface.
2023-07-04 20:12:18,032:INFO-<string>  [COLOR_GREEN]Hosting web interface on: 172.31.196.52/127.0.0.1
2023-07-04 20:12:18,084:INFO-main  Started getting token.
2023-07-04 20:12:18,093:INFO-logging  Running on http://0.0.0.0:80 (CTRL + C to quit)
2023-07-04 20:12:18,253:INFO-<string>  [COLOR_RED]Invalid cookie parsed.
2023-07-04 20:12:18,380:ERROR-base_events  Task exception was never retrieved
future: <Task finished name='Task-14' coro=<UGCSniper.get_token() done, defined at main.py:771> exception=SystemExit(1)>
Traceback (most recent call last):
  File "main.py", line 779, in get_token
    self.cookies[idx][2] = (await (await s.get("https://users.roblox.com/v1/users/authenticated",
KeyError: 'id'

During handling of the above exception, another exception occurred:

Traceback (most recent call last):
  File "main.py", line 1233, in <module>
    sniper.start()
  File "main.py", line 720, in start
    asyncio.run(self.main())
  File "/nix/store/hd4cc9rh83j291r5539hkf6qd8lgiikb-python3-3.10.8/lib/python3.10/asyncio/runners.py", line 44, in run
    return loop.run_until_complete(main)
  File "/nix/store/hd4cc9rh83j291r5539hkf6qd8lgiikb-python3-3.10.8/lib/python3.10/asyncio/base_events.py", line 636, in run_until_complete
    self.run_forever()
  File "/nix/store/hd4cc9rh83j291r5539hkf6qd8lgiikb-python3-3.10.8/lib/python3.10/asyncio/base_events.py", line 603, in run_forever
    self._run_once()
  File "/nix/store/hd4cc9rh83j291r5539hkf6qd8lgiikb-python3-3.10.8/lib/python3.10/asyncio/base_events.py", line 1899, in _run_once
    handle._run()
  File "/nix/store/hd4cc9rh83j291r5539hkf6qd8lgiikb-python3-3.10.8/lib/python3.10/asyncio/events.py", line 80, in _run
    self._context.run(self._callback, *self._args)
  File "main.py", line 784, in get_token
    exit(1)
  File "/nix/store/hd4cc9rh83j291r5539hkf6qd8lgiikb-python3-3.10.8/lib/python3.10/_sitebuiltins.py", line 26, in __call__
    raise SystemExit(code)
SystemExit: 1
2023-07-04 20:12:21,106:INFO-main  Started
2023-07-04 20:12:22,238:INFO-<string>  [COLOR_AQUAMARINE_1A]Checking for potential updates...
2023-07-04 20:12:22,326:INFO-<string>  [COLOR_AQUAMARINE_1A]No updates found.
2023-07-04 20:12:22,791:INFO-<string>  [COLOR_GREEN]Successfully started the web interface.
2023-07-04 20:12:22,792:INFO-<string>  [COLOR_GREEN]Hosting web interface on: 172.31.196.52/127.0.0.1
2023-07-04 20:12:22,833:INFO-main  Started getting token.
2023-07-04 20:12:22,838:INFO-logging  Running on http://0.0.0.0:80 (CTRL + C to quit)
2023-07-04 20:12:23,010:INFO-<string>  [COLOR_RED]Invalid cookie parsed.
2023-07-04 20:12:23,082:ERROR-base_events  Task exception was never retrieved
future: <Task finished name='Task-14' coro=<UGCSniper.get_token() done, defined at main.py:771> exception=SystemExit(1)>
Traceback (most recent call last):
  File "main.py", line 779, in get_token
    self.cookies[idx][2] = (await (await s.get("https://users.roblox.com/v1/users/authenticated",
KeyError: 'id'

During handling of the above exception, another exception occurred:

Traceback (most recent call last):
  File "main.py", line 1233, in <module>
    sniper.start()
  File "main.py", line 720, in start
    asyncio.run(self.main())
  File "/nix/store/hd4cc9rh83j291r5539hkf6qd8lgiikb-python3-3.10.8/lib/python3.10/asyncio/runners.py", line 44, in run
    return loop.run_until_complete(main)
  File "/nix/store/hd4cc9rh83j291r5539hkf6qd8lgiikb-python3-3.10.8/lib/python3.10/asyncio/base_events.py", line 636, in run_until_complete
    self.run_forever()
  File "/nix/store/hd4cc9rh83j291r5539hkf6qd8lgiikb-python3-3.10.8/lib/python3.10/asyncio/base_events.py", line 603, in run_forever
    self._run_once()
  File "/nix/store/hd4cc9rh83j291r5539hkf6qd8lgiikb-python3-3.10.8/lib/python3.10/asyncio/base_events.py", line 1899, in _run_once
    handle._run()
  File "/nix/store/hd4cc9rh83j291r5539hkf6qd8lgiikb-python3-3.10.8/lib/python3.10/asyncio/events.py", line 80, in _run
    self._context.run(self._callback, *self._args)
  File "main.py", line 784, in get_token
    exit(1)
  File "/nix/store/hd4cc9rh83j291r5539hkf6qd8lgiikb-python3-3.10.8/lib/python3.10/_sitebuiltins.py", line 26, in __call__
    raise SystemExit(code)
SystemExit: 1
2023-07-04 20:12:25,673:INFO-main  Started
2023-07-04 20:12:27,251:INFO-<string>  [COLOR_AQUAMARINE_1A]Checking for potential updates...
2023-07-04 20:12:27,338:INFO-<string>  [COLOR_AQUAMARINE_1A]No updates found.
2023-07-04 20:12:28,025:INFO-<string>  [COLOR_GREEN]Successfully started the web interface.
2023-07-04 20:12:28,026:INFO-<string>  [COLOR_GREEN]Hosting web interface on: 172.31.196.52/127.0.0.1
2023-07-04 20:12:28,062:INFO-main  Started getting token.
2023-07-04 20:12:28,070:INFO-logging  Running on http://0.0.0.0:80 (CTRL + C to quit)
2023-07-04 20:12:28,206:INFO-<string>  [COLOR_RED]Invalid cookie parsed.
2023-07-04 20:12:28,273:ERROR-base_events  Task exception was never retrieved
future: <Task finished name='Task-14' coro=<UGCSniper.get_token() done, defined at main.py:771> exception=SystemExit(1)>
Traceback (most recent call last):
  File "main.py", line 779, in get_token
    self.cookies[idx][2] = (await (await s.get("https://users.roblox.com/v1/users/authenticated",
KeyError: 'id'

During handling of the above exception, another exception occurred:

Traceback (most recent call last):
  File "main.py", line 1233, in <module>
    sniper.start()
  File "main.py", line 720, in start
    asyncio.run(self.main())
  File "/nix/store/hd4cc9rh83j291r5539hkf6qd8lgiikb-python3-3.10.8/lib/python3.10/asyncio/runners.py", line 44, in run
    return loop.run_until_complete(main)
  File "/nix/store/hd4cc9rh83j291r5539hkf6qd8lgiikb-python3-3.10.8/lib/python3.10/asyncio/base_events.py", line 636, in run_until_complete
    self.run_forever()
  File "/nix/store/hd4cc9rh83j291r5539hkf6qd8lgiikb-python3-3.10.8/lib/python3.10/asyncio/base_events.py", line 603, in run_forever
    self._run_once()
  File "/nix/store/hd4cc9rh83j291r5539hkf6qd8lgiikb-python3-3.10.8/lib/python3.10/asyncio/base_events.py", line 1899, in _run_once
    handle._run()
  File "/nix/store/hd4cc9rh83j291r5539hkf6qd8lgiikb-python3-3.10.8/lib/python3.10/asyncio/events.py", line 80, in _run
    self._context.run(self._callback, *self._args)
  File "main.py", line 784, in get_token
    exit(1)
  File "/nix/store/hd4cc9rh83j291r5539hkf6qd8lgiikb-python3-3.10.8/lib/python3.10/_sitebuiltins.py", line 26, in __call__
    raise SystemExit(code)
SystemExit: 1
2023-07-04 20:12:30,796:INFO-main  Started
2023-07-04 20:12:31,877:INFO-<string>  [COLOR_AQUAMARINE_1A]Checking for potential updates...
2023-07-04 20:12:31,995:INFO-<string>  [COLOR_AQUAMARINE_1A]No updates found.
2023-07-04 20:12:32,894:INFO-<string>  [COLOR_GREEN]Successfully started the web interface.
2023-07-04 20:12:32,894:INFO-<string>  [COLOR_GREEN]Hosting web interface on: 172.31.196.52/127.0.0.1
2023-07-04 20:12:32,942:INFO-main  Started getting token.
2023-07-04 20:12:32,970:INFO-logging  Running on http://0.0.0.0:80 (CTRL + C to quit)
2023-07-04 20:12:33,132:INFO-<string>  [COLOR_RED]Invalid cookie parsed.
2023-07-04 20:12:33,208:ERROR-base_events  Task exception was never retrieved
future: <Task finished name='Task-14' coro=<UGCSniper.get_token() done, defined at main.py:771> exception=SystemExit(1)>
Traceback (most recent call last):
  File "main.py", line 779, in get_token
    self.cookies[idx][2] = (await (await s.get("https://users.roblox.com/v1/users/authenticated",
KeyError: 'id'

During handling of the above exception, another exception occurred:

Traceback (most recent call last):
  File "main.py", line 1233, in <module>
    sniper.start()
  File "main.py", line 720, in start
    asyncio.run(self.main())
  File "/nix/store/hd4cc9rh83j291r5539hkf6qd8lgiikb-python3-3.10.8/lib/python3.10/asyncio/runners.py", line 44, in run
    return loop.run_until_complete(main)
  File "/nix/store/hd4cc9rh83j291r5539hkf6qd8lgiikb-python3-3.10.8/lib/python3.10/asyncio/base_events.py", line 636, in run_until_complete
    self.run_forever()
  File "/nix/store/hd4cc9rh83j291r5539hkf6qd8lgiikb-python3-3.10.8/lib/python3.10/asyncio/base_events.py", line 603, in run_forever
    self._run_once()
  File "/nix/store/hd4cc9rh83j291r5539hkf6qd8lgiikb-python3-3.10.8/lib/python3.10/asyncio/base_events.py", line 1899, in _run_once
    handle._run()
  File "/nix/store/hd4cc9rh83j291r5539hkf6qd8lgiikb-python3-3.10.8/lib/python3.10/asyncio/events.py", line 80, in _run
    self._context.run(self._callback, *self._args)
  File "main.py", line 784, in get_token
    exit(1)
  File "/nix/store/hd4cc9rh83j291r5539hkf6qd8lgiikb-python3-3.10.8/lib/python3.10/_sitebuiltins.py", line 26, in __call__
    raise SystemExit(code)
SystemExit: 1
2023-07-04 20:12:36,394:INFO-main  Started
2023-07-04 20:12:37,537:INFO-<string>  [COLOR_AQUAMARINE_1A]Checking for potential updates...
2023-07-04 20:12:37,665:INFO-<string>  [COLOR_AQUAMARINE_1A]No updates found.
2023-07-04 20:12:39,402:INFO-<string>  [COLOR_GREEN]Successfully started the web interface.
2023-07-04 20:12:39,404:INFO-<string>  [COLOR_GREEN]Hosting web interface on: 172.31.196.52/127.0.0.1
2023-07-04 20:12:39,443:INFO-main  Started getting token.
2023-07-04 20:12:39,480:INFO-logging  Running on http://0.0.0.0:80 (CTRL + C to quit)
2023-07-04 20:12:39,628:INFO-<string>  [COLOR_RED]Invalid cookie parsed.
2023-07-04 20:12:39,716:ERROR-base_events  Task exception was never retrieved
future: <Task finished name='Task-14' coro=<UGCSniper.get_token() done, defined at main.py:771> exception=SystemExit(1)>
Traceback (most recent call last):
  File "main.py", line 779, in get_token
    self.cookies[idx][2] = (await (await s.get("https://users.roblox.com/v1/users/authenticated",
KeyError: 'id'

During handling of the above exception, another exception occurred:

Traceback (most recent call last):
  File "main.py", line 1233, in <module>
    sniper.start()
  File "main.py", line 720, in start
    asyncio.run(self.main())
  File "/nix/store/hd4cc9rh83j291r5539hkf6qd8lgiikb-python3-3.10.8/lib/python3.10/asyncio/runners.py", line 44, in run
    return loop.run_until_complete(main)
  File "/nix/store/hd4cc9rh83j291r5539hkf6qd8lgiikb-python3-3.10.8/lib/python3.10/asyncio/base_events.py", line 636, in run_until_complete
    self.run_forever()
  File "/nix/store/hd4cc9rh83j291r5539hkf6qd8lgiikb-python3-3.10.8/lib/python3.10/asyncio/base_events.py", line 603, in run_forever
    self._run_once()
  File "/nix/store/hd4cc9rh83j291r5539hkf6qd8lgiikb-python3-3.10.8/lib/python3.10/asyncio/base_events.py", line 1899, in _run_once
    handle._run()
  File "/nix/store/hd4cc9rh83j291r5539hkf6qd8lgiikb-python3-3.10.8/lib/python3.10/asyncio/events.py", line 80, in _run
    self._context.run(self._callback, *self._args)
  File "main.py", line 784, in get_token
    exit(1)
  File "/nix/store/hd4cc9rh83j291r5539hkf6qd8lgiikb-python3-3.10.8/lib/python3.10/_sitebuiltins.py", line 26, in __call__
    raise SystemExit(code)
SystemExit: 1
